# -*- coding: utf-8 -*-

from odoo import models, fields, api, _
from odoo.exceptions import ValidationError, UserError


class XCity(models.Model):
    _name = 'logyca.city'
    _description = 'Ciudades por departamento'

    state_id = fields.Many2one('res.country.state', string='Departamento', required=True)
    code = fields.Char(string='CÃ³digo', size=10, required=True)
    name = fields.Char(string='Nombre', required=True)

    def name_get(self):
        return [(record.id, '%s' %
                 (record.name)) for record in self]
